<?xml version="1.0" ?>
<robot name="kuka_lbr_iiwa_14_r820" xmlns:xacro="http://wiki.ros.org/xacro">
  <!-- link list -->
  <link name="base_link">
    <visual>
      <origin rpy="0 0 0" xyz="0 0 0"/>
      <geometry>
        <mesh filename="robotic_arm/meshes/lbr_iiwa_14_r820/visual/base_link.dae"/>
      </geometry>
    </visual>
    <collision>
      <origin rpy="0 0 0" xyz="0 0 0"/>
      <geometry>
        <mesh filename="robotic_arm/meshes/lbr_iiwa_14_r820/collision/base_link.stl"/>
      </geometry>
    </collision>
    <inertial>
      <mass value="2.0"/>
      <origin xyz="0 0 0"/>
      <inertia ixx="0.1" ixy="0.0" ixz="0.0" iyy="0.1" iyz="0.0" izz="0.1"/>
    </inertial> 
  </link>
  <link name="link_1">
    <visual>
      <origin rpy="0 0 0" xyz="0 0 0"/>
      <geometry>
        <mesh filename="robotic_arm/meshes/lbr_iiwa_14_r820/visual/link_1.dae"/>
      </geometry>
       <material name="gray"><color rgba="0.5 0.5 0.5 1"/></material>
    </visual>
    <collision>
      <origin rpy="0 0 0" xyz="0 0 0"/>
      <geometry>
        <mesh filename="robotic_arm/meshes/lbr_iiwa_14_r820/collision/link_1.stl"/>
      </geometry>
    </collision>
    <inertial>
      <mass value="1.0"/>
      <origin xyz="0 0 0"/>
      <inertia ixx="0.1" ixy="0.0" ixz="0.0" iyy="0.1" iyz="0.0" izz="0.1"/>
    </inertial> 
  </link>
  <link name="link_2">
    <visual>
      <origin rpy="0 0 0" xyz="0 0 0"/>
      <geometry>
        <mesh filename="robotic_arm/meshes/lbr_iiwa_14_r820/visual/link_2.dae"/>
      </geometry>
       <material name="gray"><color rgba="0.5 0.5 0.5 1"/></material>
    </visual>
    <collision>
      <origin rpy="0 0 0" xyz="0 0 0"/>
      <geometry>
        <mesh filename="robotic_arm/meshes/lbr_iiwa_14_r820/collision/link_2.stl"/>
      </geometry>
    </collision>
    <inertial>
      <mass value="1.0"/>
      <origin xyz="0 0 0"/>
      <inertia ixx="0.1" ixy="0.0" ixz="0.0" iyy="0.1" iyz="0.0" izz="0.1"/>
    </inertial> 

  </link>
  <link name="link_3">
    <visual>
      <origin rpy="0 0 0" xyz="0 0 0"/>
      <geometry>
        <mesh filename="robotic_arm/meshes/lbr_iiwa_14_r820/visual/link_3.dae"/>
      </geometry>
    </visual>
    <collision>
      <origin rpy="0 0 0" xyz="0 0 0"/>
      <geometry>
        <mesh filename="robotic_arm/meshes/lbr_iiwa_14_r820/collision/link_3.stl"/>
      </geometry>
    </collision>
    <inertial>
      <mass value="0.5"/>
      <origin xyz="0 0 0"/>
      <inertia ixx="0.1" ixy="0.0" ixz="0.0" iyy="0.1" iyz="0.0" izz="0.1"/>
    </inertial> 

  </link>
  <link name="link_4">
    <visual>
      <origin rpy="0 0 0" xyz="0 0 0"/>
      <geometry>
        <mesh filename="robotic_arm/meshes/lbr_iiwa_14_r820/visual/link_4.dae"/>
      </geometry>
    </visual>
    <collision>
      <origin rpy="0 0 0" xyz="0 0 0"/>
      <geometry>
        <mesh filename="robotic_arm/meshes/lbr_iiwa_14_r820/collision/link_4.stl"/>
      </geometry>
    </collision>
    <inertial>
      <mass value="0.5"/>
      <origin xyz="0 0 0"/>
      <inertia ixx="0.1" ixy="0.0" ixz="0.0" iyy="0.1" iyz="0.0" izz="0.1"/>
    </inertial> 
  </link>
  <link name="link_5">
    <visual>
      <origin rpy="0 0 0" xyz="0 0 0"/>
      <geometry>
        <mesh filename="robotic_arm/meshes/lbr_iiwa_14_r820/visual/link_5.dae"/>
      </geometry>
    </visual>
    <collision>
      <origin rpy="0 0 0" xyz="0 0 0"/>
      <geometry>
        <mesh filename="robotic_arm/meshes/lbr_iiwa_14_r820/collision/link_5.stl"/>
      </geometry>
    </collision>
    <inertial>
      <mass value="0.25"/>
      <origin xyz="0 0 0"/>
      <inertia ixx="0.1" ixy="0.0" ixz="0.0" iyy="0.1" iyz="0.0" izz="0.1"/>
    </inertial> 
  </link>
  <link name="link_6">
    <visual>
      <origin rpy="0 0 0" xyz="0 0 0"/>
      <geometry>
        <mesh filename="robotic_arm/meshes/lbr_iiwa_14_r820/visual/link_6.dae"/>
      </geometry>
    </visual>
    <collision>
      <origin rpy="0 0 0" xyz="0 0 0"/>
      <geometry>
        <mesh filename="robotic_arm/meshes/lbr_iiwa_14_r820/collision/link_6.stl"/>
      </geometry>
    </collision>
    <inertial>
      <mass value="0.25"/>
      <origin xyz="0 0 0"/>
      <inertia ixx="0.1" ixy="0.0" ixz="0.0" iyy="0.1" iyz="0.0" izz="0.1"/>
    </inertial> 
  </link>
  <link name="link_7">
    <visual>
      <origin rpy="0 0 0" xyz="0 0 0"/>
      <geometry>
        <mesh filename="robotic_arm/meshes/lbr_iiwa_14_r820/visual/link_7.dae"/>
      </geometry>
    </visual>
    <collision>
      <origin rpy="0 0 0" xyz="0 0 0"/>
      <geometry>
        <mesh filename="robotic_arm/meshes/lbr_iiwa_14_r820/collision/link_7.stl"/>
      </geometry>
    </collision>
    <inertial>
      <mass value="0.15"/>
      <origin xyz="0 0 0"/>
      <inertia ixx="0.1" ixy="0.0" ixz="0.0" iyy="0.1" iyz="0.0" izz="0.1"/>
    </inertial> 
  </link>
  <!-- <link name="tool0"/> -->
  <!-- end of link list -->
  <!-- joint list -->
  <joint name="joint_a1" type="revolute">
    <origin rpy="0 0 0" xyz="0 0 0"/>
    <parent link="base_link"/>
    <child link="link_1"/>
    <axis xyz="0 0 1"/>
    <limit effort="0" lower="-2.9668" upper="2.9668" velocity="1.4834"/>
  </joint>
  <joint name="joint_a2" type="revolute">
    <origin rpy="0 0 0" xyz="-0.00043624 0 0.36"/>
    <parent link="link_1"/>
    <child link="link_2"/>
    <axis xyz="0 1 0"/>
    <limit effort="0" lower="-2.0942" upper="2.0942" velocity="1.4834"/>
  </joint>
  <joint name="joint_a3" type="revolute">
    <origin rpy="0 0 0" xyz="0 0 0"/>
    <parent link="link_2"/>
    <child link="link_3"/>
    <axis xyz="0 0 1"/>
    <limit effort="0" lower="-2.9668" upper="2.9668" velocity="1.7452"/>
  </joint>
  <joint name="joint_a4" type="revolute">
    <origin rpy="0 0 0" xyz="0.00043624 0 0.42"/>
    <parent link="link_3"/>
    <child link="link_4"/>
    <axis xyz="0 -1 0"/>
    <limit effort="0" lower="-2.0942" upper="2.0942" velocity="1.3089"/>
  </joint>
  <joint name="joint_a5" type="revolute">
    <origin rpy="0 0 0" xyz="0 0 0"/>
    <parent link="link_4"/>
    <child link="link_5"/>
    <axis xyz="0 0 1"/>
    <limit effort="0" lower="-2.9668" upper="2.9668" velocity="2.2688"/>
  </joint>
  <joint name="joint_a6" type="revolute">
    <origin rpy="0 0 0" xyz="0 0 0.4"/>
    <parent link="link_5"/>
    <child link="link_6"/>
    <axis xyz="0 1 0"/>
    <limit effort="0" lower="-2.0942" upper="2.0942" velocity="2.356"/>
  </joint>
  <joint name="joint_a7" type="revolute">
    <origin rpy="0 0 0" xyz="0 0 0"/>
    <parent link="link_6"/>
    <child link="link_7"/>
    <axis xyz="0 0 1"/>
    <limit effort="0" lower="-3.0541" upper="3.0541" velocity="2.356"/>
  </joint>


  
  <link name="gbase_link">
    <visual>
      <geometry>
        <mesh filename="robotiq_2f_85_gripper_visualization/meshes/visual/robotiq_arg2f_85_base_link.dae" scale="0.002 0.002 0.002"/>
      </geometry>
    </visual>
    <collision>
      <geometry>
        <mesh filename="robotiq_2f_85_gripper_visualization/meshes/visual/robotiq_arg2f_85_base_link.dae" scale="0.002 0.002 0.002"/>
      </geometry>
    </collision>
    <inertial>
      <mass value="0.2"/>
      <origin xyz="0 0 0"/>
      <inertia ixx="0.1" ixy="0.0" ixz="0.0" iyy="0.1" iyz="0.0" izz="0.1"/>
    </inertial>
  </link>

  <!-- Left Finger -->
  <link name="outer_knuckle_left">
    <visual>
      <geometry>
        <mesh filename="robotiq_2f_85_gripper_visualization/meshes/visual/robotiq_arg2f_85_outer_knuckle.dae" scale="0.002 0.002 0.002"/>
      </geometry>
    </visual>
    <collision>
      <geometry>
        <mesh filename="robotiq_2f_85_gripper_visualization/meshes/collision/robotiq_arg2f_85_outer_knuckle.dae" scale="0.002 0.002 0.002"/>
      </geometry>
    </collision>
    <inertial>
      <mass value="0.1"/>
      <origin xyz="0 0 0"/>
      <inertia ixx="0.1" ixy="0.0" ixz="0.0" iyy="0.1" iyz="0.0" izz="0.1"/>
    </inertial>
  </link>

  <link name="inner_knuckle_left">
    <visual>
      <geometry>
        <mesh filename="robotiq_2f_85_gripper_visualization/meshes/visual/robotiq_arg2f_85_inner_knuckle.dae" scale="0.002 0.002 0.002"/>
      </geometry>
    </visual>
    <collision>
      <geometry>
        <mesh filename="robotiq_2f_85_gripper_visualization/meshes/collision/robotiq_arg2f_85_inner_knuckle.dae" scale="0.002 0.002 0.002"/>
      </geometry>
    </collision>
    <inertial>
      <mass value="0.1"/>
      <origin xyz="0 0 0"/>
      <inertia ixx="0.1" ixy="0.0" ixz="0.0" iyy="0.1" iyz="0.0" izz="0.1"/>
    </inertial>
  </link>

  <link name="outer_finger_left">
    <visual>
      <geometry>
        <mesh filename="robotiq_2f_85_gripper_visualization/meshes/visual/robotiq_arg2f_85_outer_finger.dae" scale="0.002 0.002 0.002"/>
      </geometry>
    </visual>
    <collision>
      <geometry>
        <mesh filename="robotiq_2f_85_gripper_visualization/meshes/collision/robotiq_arg2f_85_outer_finger.dae" scale="0.002 0.002 0.002"/>
      </geometry>
    </collision>
    <inertial>
      <mass value="0.2"/>
      <origin xyz="0 0 0"/>
      <inertia ixx="0.1" ixy="0.0" ixz="0.0" iyy="0.1" iyz="0.0" izz="0.1"/>
    </inertial>
  </link>

  <link name="inner_finger_left">
    <visual>
      <geometry>
        <mesh filename="robotiq_2f_85_gripper_visualization\meshes\visual\robotiq_arg2f_85_inner_finger.dae" scale="0.002 0.002 0.002"/>
      </geometry>
    </visual>
    <collision>
      <geometry>
        <mesh filename="robotiq_2f_85_gripper_visualization\meshes\collision\robotiq_arg2f_85_inner_finger.dae" scale="0.002 0.002 0.002"/>
      </geometry>
    </collision>
    <inertial>
      <mass value="0.2"/>
      <origin xyz="0 0 0"/>
      <inertia ixx="0.1" ixy="0.0" ixz="0.0" iyy="0.1" iyz="0.0" izz="0.1"/>
    </inertial>
  </link>

  <link name="pad_left">
    <visual>
      <geometry>
        <mesh filename="robotiq_2f_85_gripper_visualization/meshes/visual/robotiq_arg2f_85_pad.dae" scale="0.002 0.002 0.002"/>
      </geometry>
    </visual>
    <inertial>
      <mass value="0.05"/>
      <origin xyz="0 0 0" rpy="0 0 0"/>
      <inertia ixx="0.001" ixy="0.0" ixz="0.0" iyy="0.001" iyz="0.0" izz="0.001"/>
    </inertial>
  </link>

  <!-- Right Finger (Mirrored) -->
  <!-- <link name="outer_knuckle_right">
    <visual>
      <geometry>
        <mesh filename="C:/Users/iammd/Desktop/pybullet/robotiq_2f_85_gripper_visualization/meshes/visual/robotiq_arg2f_85_outer_knuckle.dae" scale="0.002 0.002 0.002"/>
      </geometry>
    </visual>
    <collision>
      <geometry>
        <mesh filename="C:/Users/iammd/Desktop/pybullet/robotiq_2f_85_gripper_visualization/meshes/collision/robotiq_arg2f_85_outer_knuckle.dae" scale="0.002 0.002 0.002"/>
      </geometry>
    </collision>
    <inertial>
      <mass value="0.2"/>
      <origin xyz="0 0 0"/>
      <inertia ixx="0.1" ixy="0.0" ixz="0.0" iyy="0.1" iyz="0.0" izz="0.1"/>
    </inertial>
  </link>


  <link name="inner_knuckle_right">
    <visual>
      <geometry>
        <mesh filename="C:/Users/iammd/Desktop/pybullet/robotiq_2f_85_gripper_visualization/meshes/visual/robotiq_arg2f_85_inner_knuckle.dae" scale="0.002 0.002 0.002"/>
      </geometry>
    </visual>
    <collision>
      <geometry>
        <mesh filename="C:/Users/iammd\Desktop/pybullet/robotiq_2f_85_gripper_visualization/meshes/collision/robotiq_arg2f_85_inner_knuckle.dae" scale="0.002 0.002 0.002"/>
      </geometry>
    </collision>
    <inertial>
      <mass value="0.2"/>
      <origin xyz="0 0 0"/>
      <inertia ixx="0.1" ixy="0.0" ixz="0.0" iyy="0.1" iyz="0.0" izz="0.1"/>
    </inertial>
  </link>

  <link name="outer_finger_right">
    <visual>
      <geometry>
        <mesh filename="C:/Users/iammd/Desktop/pybullet/robotiq_2f_85_gripper_visualization/meshes/visual/robotiq_arg2f_85_outer_finger.dae" scale="0.002 0.002 0.002"/>
      </geometry>
    </visual>
    <collision>
      <geometry>
        <mesh filename="C:/Users/iammd/Desktop/pybullet/robotiq_2f_85_gripper_visualization/meshes/collision/robotiq_arg2f_85_outer_finger.dae" scale="0.002 0.002 0.002"/>
      </geometry>
    </collision>
    <inertial>
      <mass value="0.2"/>
      <origin xyz="0 0 0"/>
      <inertia ixx="0.1" ixy="0.0" ixz="0.0" iyy="0.1" iyz="0.0" izz="0.1"/>
    </inertial>
  </link>

  <link name="inner_finger_right">
    <visual>
      <geometry>
        <mesh filename="C:/Users/iammd/Desktop/pybullet/robotiq_2f_85_gripper_visualization/meshes/visual/robotiq_arg2f_85_inner_finger.dae" scale="0.002 0.002 0.002"/>
      </geometry>
    </visual>
    <collision>
      <geometry>
        <mesh filename="C:/Users/iammd/Desktop/pybullet/robotiq_2f_85_gripper_visualization/meshes/collision/robotiq_arg2f_85_inner_finger.dae" scale="0.002 0.002 0.002"/>
      </geometry>
    </collision>
    <inertial>
      <mass value="0.2"/>
      <origin xyz="0 0 0"/>
      <inertia ixx="0.1" ixy="0.0" ixz="0.0" iyy="0.1" iyz="0.0" izz="0.1"/>
    </inertial>
  </link>

  <link name="pad_right">
    <visual>
      <geometry>
        <mesh filename="C:/Users/iammd/Desktop/pybullet/robotiq_2f_85_gripper_visualization/meshes/visual/robotiq_arg2f_85_pad.dae" scale="0.002 0.002 0.002"/>
      </geometry>
    </visual>
    <inertial>
      <mass value="0.05"/>
      <origin xyz="0 0 0" rpy="0 0 0"/>
      <inertia ixx="0.001" ixy="0.0" ixz="0.0" iyy="0.001" iyz="0.0" izz="0.001"/>
    </inertial>
  </link> -->


  <link name="outer_knuckle_right">
    <visual>
      <geometry>
        <mesh filename="robotiq_2f_85_gripper_visualization/meshes/visual/robotiq_arg2f_85_outer_knuckle.dae" scale="0.002 0.002 0.002"/>
      </geometry>
    </visual>
    <collision>
      <geometry>
        <mesh filename="robotiq_2f_85_gripper_visualization/meshes/collision/robotiq_arg2f_85_outer_knuckle.dae" scale="0.002 0.002 0.002"/>
      </geometry>
    </collision>
    <inertial>
      <mass value="0.1"/>
      <origin xyz="0 0 0"/>
      <inertia ixx="0.1" ixy="0.0" ixz="0.0" iyy="0.1" iyz="0.0" izz="0.1"/>
    </inertial>
  </link>

  <link name="inner_knuckle_right">
    <visual>
      <geometry>
        <mesh filename="robotiq_2f_85_gripper_visualization/meshes/visual/robotiq_arg2f_85_inner_knuckle.dae" scale="0.002 0.002 0.002"/>
      </geometry>
    </visual>
    <collision>
      <geometry>
        <mesh filename="robotiq_2f_85_gripper_visualization/meshes/collision/robotiq_arg2f_85_inner_knuckle.dae" scale="0.002 0.002 0.002"/>
      </geometry>
    </collision>
    <inertial>
      <mass value="0.1"/>
      <origin xyz="0 0 0"/>
      <inertia ixx="0.1" ixy="0.0" ixz="0.0" iyy="0.1" iyz="0.0" izz="0.1"/>
    </inertial>
  </link>

  <link name="outer_finger_right">
    <visual>
      <geometry>
        <mesh filename="robotiq_2f_85_gripper_visualization/meshes/visual/robotiq_arg2f_85_outer_finger.dae" scale="0.002 0.002 0.002"/>
      </geometry>
    </visual>
    <collision>
      <geometry>
        <mesh filename="robotiq_2f_85_gripper_visualization/meshes/collision/robotiq_arg2f_85_outer_finger.dae" scale="0.002 0.002 0.002"/>
      </geometry>
    </collision>
    <inertial>
      <mass value="0.2"/>
      <origin xyz="0 0 0"/>
      <inertia ixx="0.1" ixy="0.0" ixz="0.0" iyy="0.1" iyz="0.0" izz="0.1"/>
    </inertial>
  </link>

  <link name="inner_finger_right">
    <visual>
      <geometry>
        <mesh filename="robotiq_2f_85_gripper_visualization\meshes\visual\robotiq_arg2f_85_inner_finger.dae" scale="0.002 0.002 0.002"/>
      </geometry>
    </visual>
    <collision>
      <geometry>
        <mesh filename="robotiq_2f_85_gripper_visualization\meshes\collision\robotiq_arg2f_85_inner_finger.dae" scale="0.002 0.002 0.002"/>
      </geometry>
    </collision>
    <inertial>
      <mass value="0.2"/>
      <origin xyz="0 0 0"/>
      <inertia ixx="0.1" ixy="0.0" ixz="0.0" iyy="0.1" iyz="0.0" izz="0.1"/>
    </inertial>
  </link>

  <link name="pad_right">
    <visual>
      <geometry>
        <mesh filename="robotiq_2f_85_gripper_visualization/meshes/visual/robotiq_arg2f_85_pad.dae" scale="0.002 0.002 0.002"/>
      </geometry>
    </visual>
    <inertial>
      <mass value="0.05"/>
      <origin xyz="0 0 0" rpy="0 0 0"/>
      <inertia ixx="0.001" ixy="0.0" ixz="0.0" iyy="0.001" iyz="0.0" izz="0.001"/>
    </inertial>
  </link>


  <!--JOINTS -->
<joint name="gripper_mount_joint" type="fixed">
  <parent link="link_7"/>
  <child link="gbase_link"/>
  <origin xyz="0 0 0" rpy="0 0 0"/>
</joint>


  <!-- Left Finger Joints -->
  <joint name="outer_knuckle_left_joint" type="revolute">
    <parent link="gbase_link"/>
    <child link="outer_knuckle_left"/>
    <origin xyz="0 0 0.05" rpy="0 0 0"/>
    <axis xyz="0 1 0"/>
    <limit lower="0" upper="1.0" effort="10" velocity="1.0"/>
  </joint>

  <joint name="inner_knuckle_left_joint" type="revolute">
    <parent link="outer_knuckle_left"/>
    <child link="inner_knuckle_left"/>
    <origin xyz="0 0 0.03" rpy="0 0 0"/>
    <axis xyz="0 1 0"/>
    <limit lower="0" upper="1.0" effort="10" velocity="1.0"/>
  </joint>

  <joint name="outer_finger_left_joint" type="revolute">
    <parent link="outer_knuckle_left"/>
    <child link="outer_finger_left"/>
    <origin xyz="0 0 0.05" rpy="0 0 0"/>
    <axis xyz="1 0 0"/>
    <limit lower="0" upper="1.0" effort="10" velocity="1.0"/>
  </joint>

  <joint name="inner_finger_left_joint" type="revolute">
    <parent link="inner_knuckle_left"/>
    <child link="inner_finger_left"/>
    <origin xyz="0 0 0.02" rpy="0 0 0"/>
    <axis xyz="1 0 0"/>
    <limit lower="0" upper="1.0" effort="10" velocity="1.0"/>
  </joint>

  <!-- Right Finger Joints (Mirrored) -->
  <joint name="outer_knuckle_right_joint" type="revolute">
    <parent link="gbase_link"/>
    <child link="outer_knuckle_right"/>
    <origin xyz="0 0 0.05" rpy="0 0 0"/>
    <axis xyz="0 -1 0"/>
    <limit lower="0" upper="1.0" effort="10" velocity="1.0"/>
  </joint>

  <joint name="inner_knuckle_right_joint" type="revolute">
    <parent link="outer_knuckle_right"/>
    <child link="inner_knuckle_right"/>
    <origin xyz="0 0 0.03" rpy="0 0 0"/>
    <axis xyz="0 -1 0"/>
    <limit lower="0" upper="1.0" effort="10" velocity="1.0"/>
  </joint>

  <joint name="outer_finger_right_joint" type="revolute">
    <parent link="outer_knuckle_right"/>
    <child link="outer_finger_right"/>
    <origin xyz="0 0 0.05" rpy="0 0 0"/>
    <axis xyz="-1 0 0"/>
    <limit lower="0" upper="1.0" effort="10" velocity="1.0"/>
  </joint>

  <joint name="inner_finger_right_joint" type="revolute">
    <parent link="inner_knuckle_right"/>
    <child link="inner_finger_right"/>
    <origin xyz="0 0 0.02" rpy="0 0 0"/>
    <axis xyz="-1 0 0"/>
    <limit lower="0" upper="1.0" effort="10" velocity="1.0"/>
  </joint>

  <joint name="pad_left_joint" type="fixed">
    <parent link="inner_finger_left"/>
    <child link="pad_left"/>
    <origin xyz="0 0 0.02" rpy="0 0 0"/> 
  </joint>

  <joint name="pad_right_joint" type="fixed">
    <parent link="inner_finger_right"/>
    <child link="pad_right"/>
    <origin xyz="0 0 0.02" rpy="0 0 0"/>
  </joint>
</robot>

